[2025-08-28T07:00:00.745+0000] {local_task_job_runner.py:120} INFO - ::group::Pre task execution logs
[2025-08-28T07:00:00.770+0000] {taskinstance.py:2076} INFO - Dependencies all met for dep_context=non-requeueable deps ti=<TaskInstance: minio_to_postgres.wait_for_new_file scheduled__2025-08-28T06:00:00+00:00 [queued]>
[2025-08-28T07:00:00.776+0000] {taskinstance.py:2076} INFO - Dependencies all met for dep_context=requeueable deps ti=<TaskInstance: minio_to_postgres.wait_for_new_file scheduled__2025-08-28T06:00:00+00:00 [queued]>
[2025-08-28T07:00:00.776+0000] {taskinstance.py:2306} INFO - Starting attempt 1 of 2
[2025-08-28T07:00:00.785+0000] {taskinstance.py:2330} INFO - Executing <Task(PythonSensor): wait_for_new_file> on 2025-08-28 06:00:00+00:00
[2025-08-28T07:00:00.793+0000] {standard_task_runner.py:63} INFO - Started process 824 to run task
[2025-08-28T07:00:00.796+0000] {standard_task_runner.py:90} INFO - Running: ['***', 'tasks', 'run', 'minio_to_postgres', 'wait_for_new_file', 'scheduled__2025-08-28T06:00:00+00:00', '--job-id', '664', '--raw', '--subdir', 'DAGS_FOLDER/minio_to_postgres.py', '--cfg-path', '/tmp/tmpwutxy_yi']
[2025-08-28T07:00:00.798+0000] {standard_task_runner.py:91} INFO - Job 664: Subtask wait_for_new_file
[2025-08-28T07:00:00.813+0000] {logging_mixin.py:188} WARNING - /home/***/.local/lib/python3.10/site-packages/***/settings.py:195 DeprecationWarning: The sql_alchemy_conn option in [core] has been moved to the sql_alchemy_conn option in [database] - the old setting has been used, but please update your config.
[2025-08-28T07:00:00.843+0000] {task_command.py:426} INFO - Running <TaskInstance: minio_to_postgres.wait_for_new_file scheduled__2025-08-28T06:00:00+00:00 [running]> on host 7a38bda25d96
[2025-08-28T07:00:01.104+0000] {taskinstance.py:2648} INFO - Exporting env vars: AIRFLOW_CTX_DAG_OWNER='***' AIRFLOW_CTX_DAG_ID='minio_to_postgres' AIRFLOW_CTX_TASK_ID='wait_for_new_file' AIRFLOW_CTX_EXECUTION_DATE='2025-08-28T06:00:00+00:00' AIRFLOW_CTX_TRY_NUMBER='1' AIRFLOW_CTX_DAG_RUN_ID='scheduled__2025-08-28T06:00:00+00:00'
[2025-08-28T07:00:01.105+0000] {taskinstance.py:430} INFO - ::endgroup::
[2025-08-28T07:00:01.113+0000] {python.py:75} INFO - Poking callable: <function check_new_file at 0x7f5bc71280d0>
[2025-08-28T07:01:01.244+0000] {python.py:75} INFO - Poking callable: <function check_new_file at 0x7f5bc71280d0>
[2025-08-28T07:02:01.304+0000] {python.py:75} INFO - Poking callable: <function check_new_file at 0x7f5bc71280d0>
[2025-08-28T07:03:01.368+0000] {python.py:75} INFO - Poking callable: <function check_new_file at 0x7f5bc71280d0>
[2025-08-28T07:04:01.413+0000] {python.py:75} INFO - Poking callable: <function check_new_file at 0x7f5bc71280d0>
[2025-08-28T07:05:01.489+0000] {python.py:75} INFO - Poking callable: <function check_new_file at 0x7f5bc71280d0>
[2025-08-28T07:05:01.503+0000] {taskinstance.py:441} INFO - ::group::Post task execution logs
[2025-08-28T07:05:01.503+0000] {taskinstance.py:2905} ERROR - Task failed with exception
Traceback (most recent call last):
  File "/home/airflow/.local/lib/python3.10/site-packages/airflow/models/taskinstance.py", line 465, in _execute_task
    result = _execute_callable(context=context, **execute_callable_kwargs)
  File "/home/airflow/.local/lib/python3.10/site-packages/airflow/models/taskinstance.py", line 432, in _execute_callable
    return execute_callable(context=context, **execute_callable_kwargs)
  File "/home/airflow/.local/lib/python3.10/site-packages/airflow/models/baseoperator.py", line 400, in wrapper
    return func(self, *args, **kwargs)
  File "/home/airflow/.local/lib/python3.10/site-packages/airflow/sensors/base.py", line 281, in execute
    raise AirflowSensorTimeout(message)
airflow.exceptions.AirflowSensorTimeout: Sensor has timed out; run duration of 300.3894711240009 seconds exceeds the specified timeout of 300.0.
[2025-08-28T07:05:01.521+0000] {taskinstance.py:1206} INFO - Immediate failure requested. Marking task as FAILED. dag_id=minio_to_postgres, task_id=wait_for_new_file, run_id=scheduled__2025-08-28T06:00:00+00:00, execution_date=20250828T060000, start_date=20250828T070000, end_date=20250828T070501
[2025-08-28T07:05:01.531+0000] {standard_task_runner.py:110} ERROR - Failed to execute job 664 for task wait_for_new_file (Sensor has timed out; run duration of 300.3894711240009 seconds exceeds the specified timeout of 300.0.; 824)
[2025-08-28T07:05:01.568+0000] {local_task_job_runner.py:240} INFO - Task exited with return code 1
[2025-08-28T07:05:01.590+0000] {taskinstance.py:3498} INFO - 0 downstream tasks scheduled from follow-on schedule check
[2025-08-28T07:05:01.593+0000] {local_task_job_runner.py:222} INFO - ::endgroup::
