[2025-08-28T03:31:07.970+0000] {local_task_job_runner.py:120} INFO - ::group::Pre task execution logs
[2025-08-28T03:31:07.994+0000] {taskinstance.py:2076} INFO - Dependencies all met for dep_context=non-requeueable deps ti=<TaskInstance: minio_to_postgres.load_and_track scheduled__2025-08-28T02:00:00+00:00 [queued]>
[2025-08-28T03:31:08.001+0000] {taskinstance.py:2076} INFO - Dependencies all met for dep_context=requeueable deps ti=<TaskInstance: minio_to_postgres.load_and_track scheduled__2025-08-28T02:00:00+00:00 [queued]>
[2025-08-28T03:31:08.001+0000] {taskinstance.py:2306} INFO - Starting attempt 1 of 2
[2025-08-28T03:31:08.009+0000] {taskinstance.py:2330} INFO - Executing <Task(PythonOperator): load_and_track> on 2025-08-28 02:00:00+00:00
[2025-08-28T03:31:08.015+0000] {standard_task_runner.py:63} INFO - Started process 230 to run task
[2025-08-28T03:31:08.018+0000] {standard_task_runner.py:90} INFO - Running: ['***', 'tasks', 'run', 'minio_to_postgres', 'load_and_track', 'scheduled__2025-08-28T02:00:00+00:00', '--job-id', '531', '--raw', '--subdir', 'DAGS_FOLDER/minio_to_postgres.py', '--cfg-path', '/tmp/tmpzp44l_0y']
[2025-08-28T03:31:08.020+0000] {standard_task_runner.py:91} INFO - Job 531: Subtask load_and_track
[2025-08-28T03:31:08.031+0000] {logging_mixin.py:188} WARNING - /home/***/.local/lib/python3.10/site-packages/***/settings.py:195 DeprecationWarning: The sql_alchemy_conn option in [core] has been moved to the sql_alchemy_conn option in [database] - the old setting has been used, but please update your config.
[2025-08-28T03:31:08.057+0000] {task_command.py:426} INFO - Running <TaskInstance: minio_to_postgres.load_and_track scheduled__2025-08-28T02:00:00+00:00 [running]> on host c3d91d0460b0
[2025-08-28T03:31:08.123+0000] {taskinstance.py:2648} INFO - Exporting env vars: AIRFLOW_CTX_DAG_OWNER='***' AIRFLOW_CTX_DAG_ID='minio_to_postgres' AIRFLOW_CTX_TASK_ID='load_and_track' AIRFLOW_CTX_EXECUTION_DATE='2025-08-28T02:00:00+00:00' AIRFLOW_CTX_TRY_NUMBER='1' AIRFLOW_CTX_DAG_RUN_ID='scheduled__2025-08-28T02:00:00+00:00'
[2025-08-28T03:31:08.124+0000] {taskinstance.py:430} INFO - ::endgroup::
[2025-08-28T03:31:08.267+0000] {logging_mixin.py:188} WARNING - /home/***/.local/lib/python3.10/site-packages/***/utils/context.py:320 AirflowContextDeprecationWarning: Accessing 'execution_date' from the template is deprecated and will be removed in a future version. Please use 'data_interval_start' or 'logical_date' instead.
[2025-08-28T03:31:11.351+0000] {logging_mixin.py:188} INFO - green_tripdata_2025-07.parquet → staging.green_tripdata_2025 успешно загружен.
[2025-08-28T03:31:11.354+0000] {taskinstance.py:441} INFO - ::group::Post task execution logs
[2025-08-28T03:31:11.355+0000] {taskinstance.py:2905} ERROR - Task failed with exception
Traceback (most recent call last):
  File "/home/airflow/.local/lib/python3.10/site-packages/airflow/models/taskinstance.py", line 465, in _execute_task
    result = _execute_callable(context=context, **execute_callable_kwargs)
  File "/home/airflow/.local/lib/python3.10/site-packages/airflow/models/taskinstance.py", line 432, in _execute_callable
    return execute_callable(context=context, **execute_callable_kwargs)
  File "/home/airflow/.local/lib/python3.10/site-packages/airflow/models/baseoperator.py", line 400, in wrapper
    return func(self, *args, **kwargs)
  File "/home/airflow/.local/lib/python3.10/site-packages/airflow/operators/python.py", line 235, in execute
    return_value = self.execute_callable()
  File "/home/airflow/.local/lib/python3.10/site-packages/airflow/operators/python.py", line 252, in execute_callable
    return self.python_callable(*self.op_args, **self.op_kwargs)
  File "/opt/airflow/dags/minio_to_postgres.py", line 90, in load_parquet_to_postgres
    df_csv.to_csv(CSV_TRACKING_FILE, index=False)
  File "/home/airflow/.local/lib/python3.10/site-packages/pandas/core/generic.py", line 3902, in to_csv
    return DataFrameRenderer(formatter).to_csv(
  File "/home/airflow/.local/lib/python3.10/site-packages/pandas/io/formats/format.py", line 1152, in to_csv
    csv_formatter.save()
  File "/home/airflow/.local/lib/python3.10/site-packages/pandas/io/formats/csvs.py", line 247, in save
    with get_handle(
  File "/home/airflow/.local/lib/python3.10/site-packages/pandas/io/common.py", line 739, in get_handle
    check_parent_directory(str(handle))
  File "/home/airflow/.local/lib/python3.10/site-packages/pandas/io/common.py", line 604, in check_parent_directory
    raise OSError(rf"Cannot save file into a non-existent directory: '{parent}'")
OSError: Cannot save file into a non-existent directory: '/opt/***/data'
[2025-08-28T03:31:11.364+0000] {taskinstance.py:1206} INFO - Marking task as UP_FOR_RETRY. dag_id=minio_to_postgres, task_id=load_and_track, run_id=scheduled__2025-08-28T02:00:00+00:00, execution_date=20250828T020000, start_date=20250828T033107, end_date=20250828T033111
[2025-08-28T03:31:11.372+0000] {standard_task_runner.py:110} ERROR - Failed to execute job 531 for task load_and_track (Cannot save file into a non-existent directory: '/opt/***/data'; 230)
[2025-08-28T03:31:11.397+0000] {local_task_job_runner.py:240} INFO - Task exited with return code 1
[2025-08-28T03:31:11.411+0000] {taskinstance.py:3498} INFO - 0 downstream tasks scheduled from follow-on schedule check
[2025-08-28T03:31:11.412+0000] {local_task_job_runner.py:222} INFO - ::endgroup::
