[2025-08-28T03:15:23.057+0000] {local_task_job_runner.py:120} INFO - ::group::Pre task execution logs
[2025-08-28T03:15:23.079+0000] {taskinstance.py:2076} INFO - Dependencies all met for dep_context=non-requeueable deps ti=<TaskInstance: minio_to_postgres.wait_for_new_file scheduled__2025-08-28T02:00:00+00:00 [queued]>
[2025-08-28T03:15:23.083+0000] {taskinstance.py:2076} INFO - Dependencies all met for dep_context=requeueable deps ti=<TaskInstance: minio_to_postgres.wait_for_new_file scheduled__2025-08-28T02:00:00+00:00 [queued]>
[2025-08-28T03:15:23.084+0000] {taskinstance.py:2306} INFO - Starting attempt 1 of 2
[2025-08-28T03:15:23.097+0000] {taskinstance.py:2330} INFO - Executing <Task(PythonSensor): wait_for_new_file> on 2025-08-28 02:00:00+00:00
[2025-08-28T03:15:23.102+0000] {standard_task_runner.py:63} INFO - Started process 1566 to run task
[2025-08-28T03:15:23.105+0000] {standard_task_runner.py:90} INFO - Running: ['***', 'tasks', 'run', 'minio_to_postgres', 'wait_for_new_file', 'scheduled__2025-08-28T02:00:00+00:00', '--job-id', '525', '--raw', '--subdir', 'DAGS_FOLDER/minio_to_postgres.py', '--cfg-path', '/tmp/tmpkv390w1t']
[2025-08-28T03:15:23.106+0000] {standard_task_runner.py:91} INFO - Job 525: Subtask wait_for_new_file
[2025-08-28T03:15:23.117+0000] {logging_mixin.py:188} WARNING - /home/***/.local/lib/python3.10/site-packages/***/settings.py:195 DeprecationWarning: The sql_alchemy_conn option in [core] has been moved to the sql_alchemy_conn option in [database] - the old setting has been used, but please update your config.
[2025-08-28T03:15:23.141+0000] {task_command.py:426} INFO - Running <TaskInstance: minio_to_postgres.wait_for_new_file scheduled__2025-08-28T02:00:00+00:00 [running]> on host c3d91d0460b0
[2025-08-28T03:15:23.318+0000] {taskinstance.py:2648} INFO - Exporting env vars: AIRFLOW_CTX_DAG_OWNER='***' AIRFLOW_CTX_DAG_ID='minio_to_postgres' AIRFLOW_CTX_TASK_ID='wait_for_new_file' AIRFLOW_CTX_EXECUTION_DATE='2025-08-28T02:00:00+00:00' AIRFLOW_CTX_TRY_NUMBER='1' AIRFLOW_CTX_DAG_RUN_ID='scheduled__2025-08-28T02:00:00+00:00'
[2025-08-28T03:15:23.319+0000] {taskinstance.py:430} INFO - ::endgroup::
[2025-08-28T03:15:23.325+0000] {python.py:75} INFO - Poking callable: <function check_new_file at 0x7f88cb73f9a0>
[2025-08-28T03:15:34.265+0000] {taskinstance.py:441} INFO - ::group::Post task execution logs
[2025-08-28T03:15:34.265+0000] {taskinstance.py:2905} ERROR - Task failed with exception
Traceback (most recent call last):
  File "/home/airflow/.local/lib/python3.10/site-packages/urllib3/connection.py", line 198, in _new_conn
    sock = connection.create_connection(
  File "/home/airflow/.local/lib/python3.10/site-packages/urllib3/util/connection.py", line 60, in create_connection
    for res in socket.getaddrinfo(host, port, family, socket.SOCK_STREAM):
  File "/usr/local/lib/python3.10/socket.py", line 955, in getaddrinfo
    for res in _socket.getaddrinfo(host, port, family, type, proto, flags):
socket.gaierror: [Errno -3] Temporary failure in name resolution

The above exception was the direct cause of the following exception:

Traceback (most recent call last):
  File "/home/airflow/.local/lib/python3.10/site-packages/botocore/httpsession.py", line 464, in send
    urllib_response = conn.urlopen(
  File "/home/airflow/.local/lib/python3.10/site-packages/urllib3/connectionpool.py", line 847, in urlopen
    retries = retries.increment(
  File "/home/airflow/.local/lib/python3.10/site-packages/urllib3/util/retry.py", line 445, in increment
    raise reraise(type(error), error, _stacktrace)
  File "/home/airflow/.local/lib/python3.10/site-packages/urllib3/util/util.py", line 39, in reraise
    raise value
  File "/home/airflow/.local/lib/python3.10/site-packages/urllib3/connectionpool.py", line 793, in urlopen
    response = self._make_request(
  File "/home/airflow/.local/lib/python3.10/site-packages/urllib3/connectionpool.py", line 496, in _make_request
    conn.request(
  File "/home/airflow/.local/lib/python3.10/site-packages/botocore/awsrequest.py", line 96, in request
    rval = super().request(method, url, body, headers, *args, **kwargs)
  File "/home/airflow/.local/lib/python3.10/site-packages/urllib3/connection.py", line 400, in request
    self.endheaders()
  File "/usr/local/lib/python3.10/http/client.py", line 1278, in endheaders
    self._send_output(message_body, encode_chunked=encode_chunked)
  File "/home/airflow/.local/lib/python3.10/site-packages/botocore/awsrequest.py", line 123, in _send_output
    self.send(msg)
  File "/home/airflow/.local/lib/python3.10/site-packages/botocore/awsrequest.py", line 223, in send
    return super().send(str)
  File "/usr/local/lib/python3.10/http/client.py", line 976, in send
    self.connect()
  File "/home/airflow/.local/lib/python3.10/site-packages/urllib3/connection.py", line 238, in connect
    self.sock = self._new_conn()
  File "/home/airflow/.local/lib/python3.10/site-packages/urllib3/connection.py", line 205, in _new_conn
    raise NameResolutionError(self.host, self, e) from e
urllib3.exceptions.NameResolutionError: <botocore.awsrequest.AWSHTTPConnection object at 0x7f88a81c28c0>: Failed to resolve 'minio' ([Errno -3] Temporary failure in name resolution)

During handling of the above exception, another exception occurred:

Traceback (most recent call last):
  File "/home/airflow/.local/lib/python3.10/site-packages/airflow/models/taskinstance.py", line 465, in _execute_task
    result = _execute_callable(context=context, **execute_callable_kwargs)
  File "/home/airflow/.local/lib/python3.10/site-packages/airflow/models/taskinstance.py", line 432, in _execute_callable
    return execute_callable(context=context, **execute_callable_kwargs)
  File "/home/airflow/.local/lib/python3.10/site-packages/airflow/models/baseoperator.py", line 400, in wrapper
    return func(self, *args, **kwargs)
  File "/home/airflow/.local/lib/python3.10/site-packages/airflow/sensors/base.py", line 264, in execute
    raise e
  File "/home/airflow/.local/lib/python3.10/site-packages/airflow/sensors/base.py", line 246, in execute
    poke_return = self.poke(context)
  File "/home/airflow/.local/lib/python3.10/site-packages/airflow/sensors/python.py", line 76, in poke
    return_value = self.python_callable(*self.op_args, **self.op_kwargs)
  File "/opt/airflow/dags/minio_to_postgres.py", line 34, in check_new_file
    for page in pages:
  File "/home/airflow/.local/lib/python3.10/site-packages/botocore/paginate.py", line 269, in __iter__
    response = self._make_request(current_kwargs)
  File "/home/airflow/.local/lib/python3.10/site-packages/botocore/paginate.py", line 357, in _make_request
    return self._method(**current_kwargs)
  File "/home/airflow/.local/lib/python3.10/site-packages/botocore/client.py", line 553, in _api_call
    return self._make_api_call(operation_name, kwargs)
  File "/home/airflow/.local/lib/python3.10/site-packages/botocore/client.py", line 989, in _make_api_call
    http, parsed_response = self._make_request(
  File "/home/airflow/.local/lib/python3.10/site-packages/botocore/client.py", line 1015, in _make_request
    return self._endpoint.make_request(operation_model, request_dict)
  File "/home/airflow/.local/lib/python3.10/site-packages/botocore/endpoint.py", line 119, in make_request
    return self._send_request(request_dict, operation_model)
  File "/home/airflow/.local/lib/python3.10/site-packages/botocore/endpoint.py", line 202, in _send_request
    while self._needs_retry(
  File "/home/airflow/.local/lib/python3.10/site-packages/botocore/endpoint.py", line 354, in _needs_retry
    responses = self._event_emitter.emit(
  File "/home/airflow/.local/lib/python3.10/site-packages/botocore/hooks.py", line 412, in emit
    return self._emitter.emit(aliased_event_name, **kwargs)
  File "/home/airflow/.local/lib/python3.10/site-packages/botocore/hooks.py", line 256, in emit
    return self._emit(event_name, kwargs)
  File "/home/airflow/.local/lib/python3.10/site-packages/botocore/hooks.py", line 239, in _emit
    response = handler(**kwargs)
  File "/home/airflow/.local/lib/python3.10/site-packages/botocore/retryhandler.py", line 207, in __call__
    if self._checker(**checker_kwargs):
  File "/home/airflow/.local/lib/python3.10/site-packages/botocore/retryhandler.py", line 284, in __call__
    should_retry = self._should_retry(
  File "/home/airflow/.local/lib/python3.10/site-packages/botocore/retryhandler.py", line 320, in _should_retry
    return self._checker(attempt_number, response, caught_exception)
  File "/home/airflow/.local/lib/python3.10/site-packages/botocore/retryhandler.py", line 363, in __call__
    checker_response = checker(
  File "/home/airflow/.local/lib/python3.10/site-packages/botocore/retryhandler.py", line 247, in __call__
    return self._check_caught_exception(
  File "/home/airflow/.local/lib/python3.10/site-packages/botocore/retryhandler.py", line 416, in _check_caught_exception
    raise caught_exception
  File "/home/airflow/.local/lib/python3.10/site-packages/botocore/endpoint.py", line 281, in _do_get_response
    http_response = self._send(request)
  File "/home/airflow/.local/lib/python3.10/site-packages/botocore/endpoint.py", line 377, in _send
    return self.http_session.send(request)
  File "/home/airflow/.local/lib/python3.10/site-packages/botocore/httpsession.py", line 493, in send
    raise EndpointConnectionError(endpoint_url=request.url, error=e)
botocore.exceptions.EndpointConnectionError: Could not connect to the endpoint URL: "http://minio:9000/staging?list-type=2&prefix=green_tripdata_&encoding-type=url"
[2025-08-28T03:15:34.284+0000] {taskinstance.py:1206} INFO - Marking task as UP_FOR_RETRY. dag_id=minio_to_postgres, task_id=wait_for_new_file, run_id=scheduled__2025-08-28T02:00:00+00:00, execution_date=20250828T020000, start_date=20250828T031523, end_date=20250828T031534
[2025-08-28T03:15:34.292+0000] {standard_task_runner.py:110} ERROR - Failed to execute job 525 for task wait_for_new_file (Could not connect to the endpoint URL: "http://minio:9000/staging?list-type=2&prefix=green_tripdata_&encoding-type=url"; 1566)
[2025-08-28T03:15:34.308+0000] {local_task_job_runner.py:240} INFO - Task exited with return code 1
[2025-08-28T03:15:34.323+0000] {taskinstance.py:3498} INFO - 0 downstream tasks scheduled from follow-on schedule check
[2025-08-28T03:15:34.324+0000] {local_task_job_runner.py:222} INFO - ::endgroup::
[2025-08-28T03:52:04.252+0000] {local_task_job_runner.py:120} INFO - ::group::Pre task execution logs
[2025-08-28T03:52:04.273+0000] {taskinstance.py:2076} INFO - Dependencies all met for dep_context=non-requeueable deps ti=<TaskInstance: minio_to_postgres.wait_for_new_file scheduled__2025-08-28T02:00:00+00:00 [queued]>
[2025-08-28T03:52:04.277+0000] {taskinstance.py:2076} INFO - Dependencies all met for dep_context=requeueable deps ti=<TaskInstance: minio_to_postgres.wait_for_new_file scheduled__2025-08-28T02:00:00+00:00 [queued]>
[2025-08-28T03:52:04.278+0000] {taskinstance.py:2306} INFO - Starting attempt 1 of 2
[2025-08-28T03:52:04.287+0000] {taskinstance.py:2330} INFO - Executing <Task(PythonSensor): wait_for_new_file> on 2025-08-28 02:00:00+00:00
[2025-08-28T03:52:04.292+0000] {standard_task_runner.py:63} INFO - Started process 853 to run task
[2025-08-28T03:52:04.295+0000] {standard_task_runner.py:90} INFO - Running: ['***', 'tasks', 'run', 'minio_to_postgres', 'wait_for_new_file', 'scheduled__2025-08-28T02:00:00+00:00', '--job-id', '582', '--raw', '--subdir', 'DAGS_FOLDER/minio_to_postgres.py', '--cfg-path', '/tmp/tmpb3yxdlvd']
[2025-08-28T03:52:04.296+0000] {standard_task_runner.py:91} INFO - Job 582: Subtask wait_for_new_file
[2025-08-28T03:52:04.308+0000] {logging_mixin.py:188} WARNING - /home/***/.local/lib/python3.10/site-packages/***/settings.py:195 DeprecationWarning: The sql_alchemy_conn option in [core] has been moved to the sql_alchemy_conn option in [database] - the old setting has been used, but please update your config.
[2025-08-28T03:52:04.336+0000] {task_command.py:426} INFO - Running <TaskInstance: minio_to_postgres.wait_for_new_file scheduled__2025-08-28T02:00:00+00:00 [running]> on host c3d91d0460b0
[2025-08-28T03:52:04.400+0000] {taskinstance.py:2648} INFO - Exporting env vars: AIRFLOW_CTX_DAG_OWNER='***' AIRFLOW_CTX_DAG_ID='minio_to_postgres' AIRFLOW_CTX_TASK_ID='wait_for_new_file' AIRFLOW_CTX_EXECUTION_DATE='2025-08-28T02:00:00+00:00' AIRFLOW_CTX_TRY_NUMBER='1' AIRFLOW_CTX_DAG_RUN_ID='scheduled__2025-08-28T02:00:00+00:00'
[2025-08-28T03:52:04.401+0000] {taskinstance.py:430} INFO - ::endgroup::
[2025-08-28T03:52:04.410+0000] {python.py:75} INFO - Poking callable: <function check_new_file at 0x7ff845fbbe20>
[2025-08-28T03:52:04.611+0000] {taskinstance.py:441} INFO - ::group::Post task execution logs
[2025-08-28T03:52:04.612+0000] {taskinstance.py:2905} ERROR - Task failed with exception
Traceback (most recent call last):
  File "/home/airflow/.local/lib/python3.10/site-packages/airflow/models/taskinstance.py", line 465, in _execute_task
    result = _execute_callable(context=context, **execute_callable_kwargs)
  File "/home/airflow/.local/lib/python3.10/site-packages/airflow/models/taskinstance.py", line 432, in _execute_callable
    return execute_callable(context=context, **execute_callable_kwargs)
  File "/home/airflow/.local/lib/python3.10/site-packages/airflow/models/baseoperator.py", line 400, in wrapper
    return func(self, *args, **kwargs)
  File "/home/airflow/.local/lib/python3.10/site-packages/airflow/sensors/base.py", line 264, in execute
    raise e
  File "/home/airflow/.local/lib/python3.10/site-packages/airflow/sensors/base.py", line 246, in execute
    poke_return = self.poke(context)
  File "/home/airflow/.local/lib/python3.10/site-packages/airflow/sensors/python.py", line 76, in poke
    return_value = self.python_callable(*self.op_args, **self.op_kwargs)
  File "/opt/airflow/dags/minio_to_postgres.py", line 34, in check_new_file
    for page in pages:
  File "/home/airflow/.local/lib/python3.10/site-packages/botocore/paginate.py", line 269, in __iter__
    response = self._make_request(current_kwargs)
  File "/home/airflow/.local/lib/python3.10/site-packages/botocore/paginate.py", line 357, in _make_request
    return self._method(**current_kwargs)
  File "/home/airflow/.local/lib/python3.10/site-packages/botocore/client.py", line 553, in _api_call
    return self._make_api_call(operation_name, kwargs)
  File "/home/airflow/.local/lib/python3.10/site-packages/botocore/client.py", line 1009, in _make_api_call
    raise error_class(parsed_response, operation_name)
botocore.errorfactory.NoSuchBucket: An error occurred (NoSuchBucket) when calling the ListObjectsV2 operation: The specified bucket does not exist
[2025-08-28T03:52:04.620+0000] {taskinstance.py:1206} INFO - Marking task as UP_FOR_RETRY. dag_id=minio_to_postgres, task_id=wait_for_new_file, run_id=scheduled__2025-08-28T02:00:00+00:00, execution_date=20250828T020000, start_date=20250828T035204, end_date=20250828T035204
[2025-08-28T03:52:04.627+0000] {standard_task_runner.py:110} ERROR - Failed to execute job 582 for task wait_for_new_file (An error occurred (NoSuchBucket) when calling the ListObjectsV2 operation: The specified bucket does not exist; 853)
[2025-08-28T03:52:04.667+0000] {local_task_job_runner.py:240} INFO - Task exited with return code 1
[2025-08-28T03:52:04.685+0000] {taskinstance.py:3498} INFO - 0 downstream tasks scheduled from follow-on schedule check
[2025-08-28T03:52:04.686+0000] {local_task_job_runner.py:222} INFO - ::endgroup::
