[2025-08-28T04:02:10.744+0000] {local_task_job_runner.py:120} INFO - ::group::Pre task execution logs
[2025-08-28T04:02:10.769+0000] {taskinstance.py:2076} INFO - Dependencies all met for dep_context=non-requeueable deps ti=<TaskInstance: minio_to_postgres.load_and_track manual__2025-08-28T04:02:08.611220+00:00 [queued]>
[2025-08-28T04:02:10.775+0000] {taskinstance.py:2076} INFO - Dependencies all met for dep_context=requeueable deps ti=<TaskInstance: minio_to_postgres.load_and_track manual__2025-08-28T04:02:08.611220+00:00 [queued]>
[2025-08-28T04:02:10.775+0000] {taskinstance.py:2306} INFO - Starting attempt 1 of 2
[2025-08-28T04:02:10.785+0000] {taskinstance.py:2330} INFO - Executing <Task(PythonOperator): load_and_track> on 2025-08-28 04:02:08.611220+00:00
[2025-08-28T04:02:10.790+0000] {standard_task_runner.py:63} INFO - Started process 1234 to run task
[2025-08-28T04:02:10.793+0000] {standard_task_runner.py:90} INFO - Running: ['***', 'tasks', 'run', 'minio_to_postgres', 'load_and_track', 'manual__2025-08-28T04:02:08.611220+00:00', '--job-id', '634', '--raw', '--subdir', 'DAGS_FOLDER/minio_to_postgres.py', '--cfg-path', '/tmp/tmp54q2z0i6']
[2025-08-28T04:02:10.794+0000] {standard_task_runner.py:91} INFO - Job 634: Subtask load_and_track
[2025-08-28T04:02:10.806+0000] {logging_mixin.py:188} WARNING - /home/***/.local/lib/python3.10/site-packages/***/settings.py:195 DeprecationWarning: The sql_alchemy_conn option in [core] has been moved to the sql_alchemy_conn option in [database] - the old setting has been used, but please update your config.
[2025-08-28T04:02:10.832+0000] {task_command.py:426} INFO - Running <TaskInstance: minio_to_postgres.load_and_track manual__2025-08-28T04:02:08.611220+00:00 [running]> on host c3d91d0460b0
[2025-08-28T04:02:10.892+0000] {taskinstance.py:2648} INFO - Exporting env vars: AIRFLOW_CTX_DAG_OWNER='***' AIRFLOW_CTX_DAG_ID='minio_to_postgres' AIRFLOW_CTX_TASK_ID='load_and_track' AIRFLOW_CTX_EXECUTION_DATE='2025-08-28T04:02:08.611220+00:00' AIRFLOW_CTX_TRY_NUMBER='1' AIRFLOW_CTX_DAG_RUN_ID='manual__2025-08-28T04:02:08.611220+00:00'
[2025-08-28T04:02:10.893+0000] {taskinstance.py:430} INFO - ::endgroup::
[2025-08-28T04:02:11.032+0000] {logging_mixin.py:188} WARNING - /home/***/.local/lib/python3.10/site-packages/***/utils/context.py:320 AirflowContextDeprecationWarning: Accessing 'execution_date' from the template is deprecated and will be removed in a future version. Please use 'data_interval_start' or 'logical_date' instead.
[2025-08-28T04:02:11.152+0000] {taskinstance.py:441} INFO - ::group::Post task execution logs
[2025-08-28T04:02:11.152+0000] {taskinstance.py:2905} ERROR - Task failed with exception
Traceback (most recent call last):
  File "/home/airflow/.local/lib/python3.10/site-packages/sqlalchemy/engine/base.py", line 1910, in _execute_context
    self.dialect.do_execute(
  File "/home/airflow/.local/lib/python3.10/site-packages/sqlalchemy/engine/default.py", line 736, in do_execute
    cursor.execute(statement, parameters)
psycopg2.errors.InvalidSchemaName: schema "staging" does not exist
LINE 2: CREATE TABLE staging.green_tripdata_2024 (
                     ^


The above exception was the direct cause of the following exception:

Traceback (most recent call last):
  File "/home/airflow/.local/lib/python3.10/site-packages/airflow/models/taskinstance.py", line 465, in _execute_task
    result = _execute_callable(context=context, **execute_callable_kwargs)
  File "/home/airflow/.local/lib/python3.10/site-packages/airflow/models/taskinstance.py", line 432, in _execute_callable
    return execute_callable(context=context, **execute_callable_kwargs)
  File "/home/airflow/.local/lib/python3.10/site-packages/airflow/models/baseoperator.py", line 400, in wrapper
    return func(self, *args, **kwargs)
  File "/home/airflow/.local/lib/python3.10/site-packages/airflow/operators/python.py", line 235, in execute
    return_value = self.execute_callable()
  File "/home/airflow/.local/lib/python3.10/site-packages/airflow/operators/python.py", line 252, in execute_callable
    return self.python_callable(*self.op_args, **self.op_kwargs)
  File "/opt/airflow/dags/minio_to_postgres.py", line 76, in load_parquet_to_postgres
    df.to_sql(
  File "/home/airflow/.local/lib/python3.10/site-packages/pandas/util/_decorators.py", line 333, in wrapper
    return func(*args, **kwargs)
  File "/home/airflow/.local/lib/python3.10/site-packages/pandas/core/generic.py", line 3008, in to_sql
    return sql.to_sql(
  File "/home/airflow/.local/lib/python3.10/site-packages/pandas/io/sql.py", line 788, in to_sql
    return pandas_sql.to_sql(
  File "/home/airflow/.local/lib/python3.10/site-packages/pandas/io/sql.py", line 1948, in to_sql
    table = self.prep_table(
  File "/home/airflow/.local/lib/python3.10/site-packages/pandas/io/sql.py", line 1852, in prep_table
    table.create()
  File "/home/airflow/.local/lib/python3.10/site-packages/pandas/io/sql.py", line 936, in create
    self._execute_create()
  File "/home/airflow/.local/lib/python3.10/site-packages/pandas/io/sql.py", line 922, in _execute_create
    self.table.create(bind=self.pd_sql.con)
  File "/home/airflow/.local/lib/python3.10/site-packages/sqlalchemy/sql/schema.py", line 962, in create
    bind._run_ddl_visitor(ddl.SchemaGenerator, self, checkfirst=checkfirst)
  File "/home/airflow/.local/lib/python3.10/site-packages/sqlalchemy/engine/base.py", line 2221, in _run_ddl_visitor
    visitorcallable(self.dialect, self, **kwargs).traverse_single(element)
  File "/home/airflow/.local/lib/python3.10/site-packages/sqlalchemy/sql/visitors.py", line 524, in traverse_single
    return meth(obj, **kw)
  File "/home/airflow/.local/lib/python3.10/site-packages/sqlalchemy/sql/ddl.py", line 899, in visit_table
    self.connection.execute(
  File "/home/airflow/.local/lib/python3.10/site-packages/sqlalchemy/engine/base.py", line 1385, in execute
    return meth(self, multiparams, params, _EMPTY_EXECUTION_OPTS)
  File "/home/airflow/.local/lib/python3.10/site-packages/sqlalchemy/sql/ddl.py", line 80, in _execute_on_connection
    return connection._execute_ddl(
  File "/home/airflow/.local/lib/python3.10/site-packages/sqlalchemy/engine/base.py", line 1477, in _execute_ddl
    ret = self._execute_context(
  File "/home/airflow/.local/lib/python3.10/site-packages/sqlalchemy/engine/base.py", line 1953, in _execute_context
    self._handle_dbapi_exception(
  File "/home/airflow/.local/lib/python3.10/site-packages/sqlalchemy/engine/base.py", line 2134, in _handle_dbapi_exception
    util.raise_(
  File "/home/airflow/.local/lib/python3.10/site-packages/sqlalchemy/util/compat.py", line 211, in raise_
    raise exception
  File "/home/airflow/.local/lib/python3.10/site-packages/sqlalchemy/engine/base.py", line 1910, in _execute_context
    self.dialect.do_execute(
  File "/home/airflow/.local/lib/python3.10/site-packages/sqlalchemy/engine/default.py", line 736, in do_execute
    cursor.execute(statement, parameters)
sqlalchemy.exc.ProgrammingError: (psycopg2.errors.InvalidSchemaName) schema "staging" does not exist
LINE 2: CREATE TABLE staging.green_tripdata_2024 (
                     ^

[SQL: 
CREATE TABLE staging.green_tripdata_2024 (
	"VendorID" INTEGER, 
	lpep_pickup_datetime TIMESTAMP WITHOUT TIME ZONE, 
	lpep_dropoff_datetime TIMESTAMP WITHOUT TIME ZONE, 
	store_and_fwd_flag TEXT, 
	"RatecodeID" FLOAT(53), 
	"PULocationID" INTEGER, 
	"DOLocationID" INTEGER, 
	passenger_count FLOAT(53), 
	trip_distance FLOAT(53), 
	fare_amount FLOAT(53), 
	extra FLOAT(53), 
	mta_tax FLOAT(53), 
	tip_amount FLOAT(53), 
	tolls_amount FLOAT(53), 
	ehail_fee FLOAT(53), 
	improvement_surcharge FLOAT(53), 
	total_amount FLOAT(53), 
	payment_type FLOAT(53), 
	trip_type FLOAT(53), 
	congestion_surcharge FLOAT(53)
)

]
(Background on this error at: https://sqlalche.me/e/14/f405)
[2025-08-28T04:02:11.165+0000] {taskinstance.py:1206} INFO - Marking task as UP_FOR_RETRY. dag_id=minio_to_postgres, task_id=load_and_track, run_id=manual__2025-08-28T04:02:08.611220+00:00, execution_date=20250828T040208, start_date=20250828T040210, end_date=20250828T040211
[2025-08-28T04:02:11.172+0000] {standard_task_runner.py:110} ERROR - Failed to execute job 634 for task load_and_track ((psycopg2.errors.InvalidSchemaName) schema "staging" does not exist
LINE 2: CREATE TABLE staging.green_tripdata_2024 (
                     ^

[SQL: 
CREATE TABLE staging.green_tripdata_2024 (
	"VendorID" INTEGER, 
	lpep_pickup_datetime TIMESTAMP WITHOUT TIME ZONE, 
	lpep_dropoff_datetime TIMESTAMP WITHOUT TIME ZONE, 
	store_and_fwd_flag TEXT, 
	"RatecodeID" FLOAT(53), 
	"PULocationID" INTEGER, 
	"DOLocationID" INTEGER, 
	passenger_count FLOAT(53), 
	trip_distance FLOAT(53), 
	fare_amount FLOAT(53), 
	extra FLOAT(53), 
	mta_tax FLOAT(53), 
	tip_amount FLOAT(53), 
	tolls_amount FLOAT(53), 
	ehail_fee FLOAT(53), 
	improvement_surcharge FLOAT(53), 
	total_amount FLOAT(53), 
	payment_type FLOAT(53), 
	trip_type FLOAT(53), 
	congestion_surcharge FLOAT(53)
)

]
(Background on this error at: https://sqlalche.me/e/14/f405); 1234)
[2025-08-28T04:02:11.205+0000] {local_task_job_runner.py:240} INFO - Task exited with return code 1
[2025-08-28T04:02:11.220+0000] {taskinstance.py:3498} INFO - 0 downstream tasks scheduled from follow-on schedule check
[2025-08-28T04:02:11.221+0000] {local_task_job_runner.py:222} INFO - ::endgroup::
