[2025-08-01T04:31:44.319+0000] {local_task_job_runner.py:120} INFO - ::group::Pre task execution logs
[2025-08-01T04:31:44.342+0000] {taskinstance.py:2076} INFO - Dependencies all met for dep_context=non-requeueable deps ti=<TaskInstance: parquet_in_minio.download_parquet scheduled__2023-09-01T00:00:00+00:00 [queued]>
[2025-08-01T04:31:44.348+0000] {taskinstance.py:2076} INFO - Dependencies all met for dep_context=requeueable deps ti=<TaskInstance: parquet_in_minio.download_parquet scheduled__2023-09-01T00:00:00+00:00 [queued]>
[2025-08-01T04:31:44.348+0000] {taskinstance.py:2306} INFO - Starting attempt 1 of 6
[2025-08-01T04:31:44.359+0000] {taskinstance.py:2330} INFO - Executing <Task(PythonOperator): download_parquet> on 2023-09-01 00:00:00+00:00
[2025-08-01T04:31:44.364+0000] {standard_task_runner.py:63} INFO - Started process 1506 to run task
[2025-08-01T04:31:44.367+0000] {standard_task_runner.py:90} INFO - Running: ['***', 'tasks', 'run', 'parquet_in_minio', 'download_parquet', 'scheduled__2023-09-01T00:00:00+00:00', '--job-id', '352', '--raw', '--subdir', 'DAGS_FOLDER/parquet_to_minio.py', '--cfg-path', '/tmp/tmpynzaxbo_']
[2025-08-01T04:31:44.368+0000] {standard_task_runner.py:91} INFO - Job 352: Subtask download_parquet
[2025-08-01T04:31:44.383+0000] {logging_mixin.py:188} WARNING - /home/***/.local/lib/python3.10/site-packages/***/settings.py:195 DeprecationWarning: The sql_alchemy_conn option in [core] has been moved to the sql_alchemy_conn option in [database] - the old setting has been used, but please update your config.
[2025-08-01T04:31:44.411+0000] {task_command.py:426} INFO - Running <TaskInstance: parquet_in_minio.download_parquet scheduled__2023-09-01T00:00:00+00:00 [running]> on host 87b19f697adc
[2025-08-01T04:31:44.490+0000] {taskinstance.py:2648} INFO - Exporting env vars: AIRFLOW_CTX_DAG_OWNER='***' AIRFLOW_CTX_DAG_ID='parquet_in_minio' AIRFLOW_CTX_TASK_ID='download_parquet' AIRFLOW_CTX_EXECUTION_DATE='2023-09-01T00:00:00+00:00' AIRFLOW_CTX_TRY_NUMBER='1' AIRFLOW_CTX_DAG_RUN_ID='scheduled__2023-09-01T00:00:00+00:00'
[2025-08-01T04:31:44.491+0000] {taskinstance.py:430} INFO - ::endgroup::
[2025-08-01T04:31:44.500+0000] {logging_mixin.py:188} WARNING - /home/***/.local/lib/python3.10/site-packages/***/utils/context.py:320 AirflowContextDeprecationWarning: Accessing 'execution_date' from the template is deprecated and will be removed in a future version. Please use 'data_interval_start' or 'logical_date' instead.
[2025-08-01T04:31:47.994+0000] {python.py:237} INFO - Done. Returned value was: None
[2025-08-01T04:31:47.995+0000] {taskinstance.py:441} INFO - ::group::Post task execution logs
[2025-08-01T04:31:48.002+0000] {taskinstance.py:1206} INFO - Marking task as SUCCESS. dag_id=parquet_in_minio, task_id=download_parquet, run_id=scheduled__2023-09-01T00:00:00+00:00, execution_date=20230901T000000, start_date=20250801T043144, end_date=20250801T043148
[2025-08-01T04:31:48.025+0000] {local_task_job_runner.py:240} INFO - Task exited with return code 0
[2025-08-01T04:31:48.046+0000] {taskinstance.py:3498} INFO - 1 downstream tasks scheduled from follow-on schedule check
[2025-08-01T04:31:48.047+0000] {local_task_job_runner.py:222} INFO - ::endgroup::
[2025-08-28T03:48:52.980+0000] {local_task_job_runner.py:120} INFO - ::group::Pre task execution logs
[2025-08-28T03:48:53.005+0000] {taskinstance.py:2076} INFO - Dependencies all met for dep_context=non-requeueable deps ti=<TaskInstance: parquet_in_minio.download_parquet scheduled__2023-09-01T00:00:00+00:00 [queued]>
[2025-08-28T03:48:53.012+0000] {taskinstance.py:2076} INFO - Dependencies all met for dep_context=requeueable deps ti=<TaskInstance: parquet_in_minio.download_parquet scheduled__2023-09-01T00:00:00+00:00 [queued]>
[2025-08-28T03:48:53.013+0000] {taskinstance.py:2306} INFO - Starting attempt 1 of 6
[2025-08-28T03:48:53.023+0000] {taskinstance.py:2330} INFO - Executing <Task(PythonOperator): download_parquet> on 2023-09-01 00:00:00+00:00
[2025-08-28T03:48:53.028+0000] {standard_task_runner.py:63} INFO - Started process 690 to run task
[2025-08-28T03:48:53.031+0000] {standard_task_runner.py:90} INFO - Running: ['***', 'tasks', 'run', 'parquet_in_minio', 'download_parquet', 'scheduled__2023-09-01T00:00:00+00:00', '--job-id', '545', '--raw', '--subdir', 'DAGS_FOLDER/parquet_to_minio.py', '--cfg-path', '/tmp/tmptfp3zgoh']
[2025-08-28T03:48:53.033+0000] {standard_task_runner.py:91} INFO - Job 545: Subtask download_parquet
[2025-08-28T03:48:53.047+0000] {logging_mixin.py:188} WARNING - /home/***/.local/lib/python3.10/site-packages/***/settings.py:195 DeprecationWarning: The sql_alchemy_conn option in [core] has been moved to the sql_alchemy_conn option in [database] - the old setting has been used, but please update your config.
[2025-08-28T03:48:53.083+0000] {task_command.py:426} INFO - Running <TaskInstance: parquet_in_minio.download_parquet scheduled__2023-09-01T00:00:00+00:00 [running]> on host c3d91d0460b0
[2025-08-28T03:48:53.152+0000] {taskinstance.py:2648} INFO - Exporting env vars: AIRFLOW_CTX_DAG_OWNER='***' AIRFLOW_CTX_DAG_ID='parquet_in_minio' AIRFLOW_CTX_TASK_ID='download_parquet' AIRFLOW_CTX_EXECUTION_DATE='2023-09-01T00:00:00+00:00' AIRFLOW_CTX_TRY_NUMBER='1' AIRFLOW_CTX_DAG_RUN_ID='scheduled__2023-09-01T00:00:00+00:00'
[2025-08-28T03:48:53.153+0000] {taskinstance.py:430} INFO - ::endgroup::
[2025-08-28T03:48:53.164+0000] {logging_mixin.py:188} WARNING - /home/***/.local/lib/python3.10/site-packages/***/utils/context.py:320 AirflowContextDeprecationWarning: Accessing 'execution_date' from the template is deprecated and will be removed in a future version. Please use 'data_interval_start' or 'logical_date' instead.
[2025-08-28T03:49:32.917+0000] {taskinstance.py:441} INFO - ::group::Post task execution logs
[2025-08-28T03:49:32.917+0000] {taskinstance.py:2905} ERROR - Task failed with exception
Traceback (most recent call last):
  File "/home/airflow/.local/lib/python3.10/site-packages/urllib3/connectionpool.py", line 793, in urlopen
    response = self._make_request(
  File "/home/airflow/.local/lib/python3.10/site-packages/urllib3/connectionpool.py", line 537, in _make_request
    response = conn.getresponse()
  File "/home/airflow/.local/lib/python3.10/site-packages/urllib3/connection.py", line 466, in getresponse
    httplib_response = super().getresponse()
  File "/usr/local/lib/python3.10/http/client.py", line 1375, in getresponse
    response.begin()
  File "/usr/local/lib/python3.10/http/client.py", line 318, in begin
    version, status, reason = self._read_status()
  File "/usr/local/lib/python3.10/http/client.py", line 287, in _read_status
    raise RemoteDisconnected("Remote end closed connection without"
http.client.RemoteDisconnected: Remote end closed connection without response

During handling of the above exception, another exception occurred:

Traceback (most recent call last):
  File "/home/airflow/.local/lib/python3.10/site-packages/requests/adapters.py", line 486, in send
    resp = conn.urlopen(
  File "/home/airflow/.local/lib/python3.10/site-packages/urllib3/connectionpool.py", line 847, in urlopen
    retries = retries.increment(
  File "/home/airflow/.local/lib/python3.10/site-packages/urllib3/util/retry.py", line 470, in increment
    raise reraise(type(error), error, _stacktrace)
  File "/home/airflow/.local/lib/python3.10/site-packages/urllib3/util/util.py", line 38, in reraise
    raise value.with_traceback(tb)
  File "/home/airflow/.local/lib/python3.10/site-packages/urllib3/connectionpool.py", line 793, in urlopen
    response = self._make_request(
  File "/home/airflow/.local/lib/python3.10/site-packages/urllib3/connectionpool.py", line 537, in _make_request
    response = conn.getresponse()
  File "/home/airflow/.local/lib/python3.10/site-packages/urllib3/connection.py", line 466, in getresponse
    httplib_response = super().getresponse()
  File "/usr/local/lib/python3.10/http/client.py", line 1375, in getresponse
    response.begin()
  File "/usr/local/lib/python3.10/http/client.py", line 318, in begin
    version, status, reason = self._read_status()
  File "/usr/local/lib/python3.10/http/client.py", line 287, in _read_status
    raise RemoteDisconnected("Remote end closed connection without"
urllib3.exceptions.ProtocolError: ('Connection aborted.', RemoteDisconnected('Remote end closed connection without response'))

During handling of the above exception, another exception occurred:

Traceback (most recent call last):
  File "/home/airflow/.local/lib/python3.10/site-packages/airflow/models/taskinstance.py", line 465, in _execute_task
    result = _execute_callable(context=context, **execute_callable_kwargs)
  File "/home/airflow/.local/lib/python3.10/site-packages/airflow/models/taskinstance.py", line 432, in _execute_callable
    return execute_callable(context=context, **execute_callable_kwargs)
  File "/home/airflow/.local/lib/python3.10/site-packages/airflow/models/baseoperator.py", line 400, in wrapper
    return func(self, *args, **kwargs)
  File "/home/airflow/.local/lib/python3.10/site-packages/airflow/operators/python.py", line 235, in execute
    return_value = self.execute_callable()
  File "/home/airflow/.local/lib/python3.10/site-packages/airflow/operators/python.py", line 252, in execute_callable
    return self.python_callable(*self.op_args, **self.op_kwargs)
  File "/opt/airflow/dags/parquet_to_minio.py", line 20, in download_parquet
    response = requests.get(PARQUET_URL, stream=True)
  File "/home/airflow/.local/lib/python3.10/site-packages/requests/api.py", line 73, in get
    return request("get", url, params=params, **kwargs)
  File "/home/airflow/.local/lib/python3.10/site-packages/requests/api.py", line 59, in request
    return session.request(method=method, url=url, **kwargs)
  File "/home/airflow/.local/lib/python3.10/site-packages/requests/sessions.py", line 589, in request
    resp = self.send(prep, **send_kwargs)
  File "/home/airflow/.local/lib/python3.10/site-packages/requests/sessions.py", line 703, in send
    r = adapter.send(request, **kwargs)
  File "/home/airflow/.local/lib/python3.10/site-packages/requests/adapters.py", line 501, in send
    raise ConnectionError(err, request=request)
requests.exceptions.ConnectionError: ('Connection aborted.', RemoteDisconnected('Remote end closed connection without response'))
[2025-08-28T03:49:32.927+0000] {taskinstance.py:1206} INFO - Marking task as UP_FOR_RETRY. dag_id=parquet_in_minio, task_id=download_parquet, run_id=scheduled__2023-09-01T00:00:00+00:00, execution_date=20230901T000000, start_date=20250828T034853, end_date=20250828T034932
[2025-08-28T03:49:32.935+0000] {standard_task_runner.py:110} ERROR - Failed to execute job 545 for task download_parquet (('Connection aborted.', RemoteDisconnected('Remote end closed connection without response')); 690)
[2025-08-28T03:49:32.956+0000] {local_task_job_runner.py:240} INFO - Task exited with return code 1
[2025-08-28T03:49:32.971+0000] {taskinstance.py:3498} INFO - 0 downstream tasks scheduled from follow-on schedule check
[2025-08-28T03:49:32.972+0000] {local_task_job_runner.py:222} INFO - ::endgroup::
