[2025-08-28T03:55:09.442+0000] {local_task_job_runner.py:120} INFO - ::group::Pre task execution logs
[2025-08-28T03:55:09.461+0000] {taskinstance.py:2076} INFO - Dependencies all met for dep_context=non-requeueable deps ti=<TaskInstance: minio_to_postgres.wait_for_new_file manual__2025-08-28T03:52:06.632241+00:00 [queued]>
[2025-08-28T03:55:09.465+0000] {taskinstance.py:2076} INFO - Dependencies all met for dep_context=requeueable deps ti=<TaskInstance: minio_to_postgres.wait_for_new_file manual__2025-08-28T03:52:06.632241+00:00 [queued]>
[2025-08-28T03:55:09.465+0000] {taskinstance.py:2306} INFO - Starting attempt 2 of 2
[2025-08-28T03:55:09.472+0000] {taskinstance.py:2330} INFO - Executing <Task(PythonSensor): wait_for_new_file> on 2025-08-28 03:52:06.632241+00:00
[2025-08-28T03:55:09.477+0000] {standard_task_runner.py:63} INFO - Started process 1051 to run task
[2025-08-28T03:55:09.480+0000] {standard_task_runner.py:90} INFO - Running: ['***', 'tasks', 'run', 'minio_to_postgres', 'wait_for_new_file', 'manual__2025-08-28T03:52:06.632241+00:00', '--job-id', '626', '--raw', '--subdir', 'DAGS_FOLDER/minio_to_postgres.py', '--cfg-path', '/tmp/tmpwne51kqs']
[2025-08-28T03:55:09.481+0000] {standard_task_runner.py:91} INFO - Job 626: Subtask wait_for_new_file
[2025-08-28T03:55:09.495+0000] {logging_mixin.py:188} WARNING - /home/***/.local/lib/python3.10/site-packages/***/settings.py:195 DeprecationWarning: The sql_alchemy_conn option in [core] has been moved to the sql_alchemy_conn option in [database] - the old setting has been used, but please update your config.
[2025-08-28T03:55:09.518+0000] {task_command.py:426} INFO - Running <TaskInstance: minio_to_postgres.wait_for_new_file manual__2025-08-28T03:52:06.632241+00:00 [running]> on host c3d91d0460b0
[2025-08-28T03:55:09.571+0000] {taskinstance.py:2648} INFO - Exporting env vars: AIRFLOW_CTX_DAG_OWNER='***' AIRFLOW_CTX_DAG_ID='minio_to_postgres' AIRFLOW_CTX_TASK_ID='wait_for_new_file' AIRFLOW_CTX_EXECUTION_DATE='2025-08-28T03:52:06.632241+00:00' AIRFLOW_CTX_TRY_NUMBER='2' AIRFLOW_CTX_DAG_RUN_ID='manual__2025-08-28T03:52:06.632241+00:00'
[2025-08-28T03:55:09.571+0000] {taskinstance.py:430} INFO - ::endgroup::
[2025-08-28T03:55:09.580+0000] {python.py:75} INFO - Poking callable: <function check_new_file at 0x7ff845fbbe20>
[2025-08-28T03:55:09.770+0000] {taskinstance.py:441} INFO - ::group::Post task execution logs
[2025-08-28T03:55:09.770+0000] {taskinstance.py:2905} ERROR - Task failed with exception
Traceback (most recent call last):
  File "/home/airflow/.local/lib/python3.10/site-packages/airflow/models/taskinstance.py", line 465, in _execute_task
    result = _execute_callable(context=context, **execute_callable_kwargs)
  File "/home/airflow/.local/lib/python3.10/site-packages/airflow/models/taskinstance.py", line 432, in _execute_callable
    return execute_callable(context=context, **execute_callable_kwargs)
  File "/home/airflow/.local/lib/python3.10/site-packages/airflow/models/baseoperator.py", line 400, in wrapper
    return func(self, *args, **kwargs)
  File "/home/airflow/.local/lib/python3.10/site-packages/airflow/sensors/base.py", line 264, in execute
    raise e
  File "/home/airflow/.local/lib/python3.10/site-packages/airflow/sensors/base.py", line 246, in execute
    poke_return = self.poke(context)
  File "/home/airflow/.local/lib/python3.10/site-packages/airflow/sensors/python.py", line 76, in poke
    return_value = self.python_callable(*self.op_args, **self.op_kwargs)
  File "/opt/airflow/dags/minio_to_postgres.py", line 34, in check_new_file
    for page in pages:
  File "/home/airflow/.local/lib/python3.10/site-packages/botocore/paginate.py", line 269, in __iter__
    response = self._make_request(current_kwargs)
  File "/home/airflow/.local/lib/python3.10/site-packages/botocore/paginate.py", line 357, in _make_request
    return self._method(**current_kwargs)
  File "/home/airflow/.local/lib/python3.10/site-packages/botocore/client.py", line 553, in _api_call
    return self._make_api_call(operation_name, kwargs)
  File "/home/airflow/.local/lib/python3.10/site-packages/botocore/client.py", line 1009, in _make_api_call
    raise error_class(parsed_response, operation_name)
botocore.errorfactory.NoSuchBucket: An error occurred (NoSuchBucket) when calling the ListObjectsV2 operation: The specified bucket does not exist
[2025-08-28T03:55:09.777+0000] {taskinstance.py:1206} INFO - Marking task as FAILED. dag_id=minio_to_postgres, task_id=wait_for_new_file, run_id=manual__2025-08-28T03:52:06.632241+00:00, execution_date=20250828T035206, start_date=20250828T035509, end_date=20250828T035509
[2025-08-28T03:55:09.784+0000] {standard_task_runner.py:110} ERROR - Failed to execute job 626 for task wait_for_new_file (An error occurred (NoSuchBucket) when calling the ListObjectsV2 operation: The specified bucket does not exist; 1051)
[2025-08-28T03:55:09.812+0000] {local_task_job_runner.py:240} INFO - Task exited with return code 1
[2025-08-28T03:55:09.838+0000] {taskinstance.py:3498} INFO - 0 downstream tasks scheduled from follow-on schedule check
[2025-08-28T03:55:09.841+0000] {local_task_job_runner.py:222} INFO - ::endgroup::
